<mujoco>
    <option timestep="0.0001"/>
    <option gravity="0 0 -9.81"/>
    <worldbody>
        <geom type="plane" size="10 10 0.1" pos="0 0 -0.5" rgba="1 0 0 1"/>
        <light diffuse="0.7 0.7 0.7" pos="0 0 3"/>
            <body name="arm" pos="0 0 0">
                <geom type="box" size="0.10 0.025 0.015" pos="0 0 0" rgba="0 0.8 0.2 1" mass="0.02"/>
                <body pos="0.12 0 0">
                    <joint name="elbow_joint" pos="0 0 0" axis="0 1 0"/>
                    <geom type="cylinder" size="0.0198 0.03" pos="0 0 0" euler="90 0 0" rgba="0.1 0.1 0.1 1" mass="0.065"/>
                    <body pos="0.1 0 0">
                        <geom type="box" size="0.1 0.025 0.015" pos="0 0 0" rgba="1 0 1 1" mass="0.02"/>      

                        <!-- <geom type="box" size="0.1 0.012 0.01" pos="0 0 0" rgba="1 0 1 1" mass="0.02"/>       -->
                    </body>
                </body>
            </body>
    </worldbody>
</mujoco>


<!-- <mujoco>
    <worldbody>
        <geom type="plane" size="10 10 0.1" pos="0 0 -0.5" rgba="1 0 0 1"/>
        <light diffuse="0.7 0.7 0.7" pos="0 0 3"/>

        <body>
            <geom type="box" size="0.075 0.03 0.015" size="" rgba="0.5 0.5 0.5 1"/>
            <!-- <body name="link1">
                <joint pos="0 0 0" axis="0 1 0">

            </body> -->

        </body>
    </worldbody>
</mujoco>

